Workbook

Sheet Tableau de bord
A1: MATHO CM2 – TABLEAU DE BORD DU PROJET
A2: Tous les chiffres se calculent automatiquement à partir des feuilles « Notions », « Livrables » et « Phasage ».
A4: Notions au référentiel | B4: =COUNTA(Notions!A2:A69) -> 68
A5: Avancement global (production) | B5: =AVERAGE(Notions!Q2:Q69) -> 0.072259358
A6: Notions terminées | B6: =COUNTIF(Notions!R2:R69,"Terminé") -> 0
A7: Notions en cours | B7: =COUNTIF(Notions!R2:R69,"En cours") -> 1
A8: Notions non démarrées | B8: =COUNTIF(Notions!R2:R69,"Non démarré") -> 67
A9: Fiches validées par des enseignants | B9: =COUNTIF(Notions!G2:G69,"Validé") -> 0
A10: Budget API consommé | B10: ='Budget API'!B22 -> 0 | C10: ='Budget API'!B23 -> NORMAL
A11: AVANCEMENT PAR DOMAINE
A12: Domaine | B12: Nb notions | C12: Avancement moyen | D12: Terminées
A13: D1 – Numération | B13: =COUNTIF(Notions!$B$2:$B$69,A13) -> 3 | C13: =IFERROR(AVERAGEIF(Notions!$B$2:$B$69,A13,Notions!$Q$2:$Q$69),0) -> 0.068181818 | D13: =COUNTIFS(Notions!$B$2:$B$69,A13,Notions!$R$2:$R$69,"Terminé") -> 0
A14: D2 – Nombres décimaux | B14: =COUNTIF(Notions!$B$2:$B$69,A14) -> 4 | C14: =IFERROR(AVERAGEIF(Notions!$B$2:$B$69,A14,Notions!$Q$2:$Q$69),0) -> 0.068181818 | D14: =COUNTIFS(Notions!$B$2:$B$69,A14,Notions!$R$2:$R$69,"Terminé") -> 0
A15: D3 – Calcul | B15: =COUNTIF(Notions!$B$2:$B$69,A15) -> 9 | C15: =IFERROR(AVERAGEIF(Notions!$B$2:$B$69,A15,Notions!$Q$2:$Q$69),0) -> 0.068181818 | D15: =COUNTIFS(Notions!$B$2:$B$69,A15,Notions!$R$2:$R$69,"Terminé") -> 0
A16: D4 – Fractions | B16: =COUNTIF(Notions!$B$2:$B$69,A16) -> 7 | C16: =IFERROR(AVERAGEIF(Notions!$B$2:$B$69,A16,Notions!$Q$2:$Q$69),0) -> 0.10779221 | D16: =COUNTIFS(Notions!$B$2:$B$69,A16,Notions!$R$2:$R$69,"Terminé") -> 0
A17: D5 – Proportionnalité | B17: =COUNTIF(Notions!$B$2:$B$69,A17) -> 7 | C17: =IFERROR(AVERAGEIF(Notions!$B$2:$B$69,A17,Notions!$Q$2:$Q$69),0) -> 0.068181818 | D17: =COUNTIFS(Notions!$B$2:$B$69,A17,Notions!$R$2:$R$69,"Terminé") -> 0
A18: D6 – Grandeurs et mesures | B18: =COUNTIF(Notions!$B$2:$B$69,A18) -> 9 | C18: =IFERROR(AVERAGEIF(Notions!$B$2:$B$69,A18,Notions!$Q$2:$Q$69),0) -> 0.068181818 | D18: =COUNTIFS(Notions!$B$2:$B$69,A18,Notions!$R$2:$R$69,"Terminé") -> 0
A19: D7 – Géométrie plane | B19: =COUNTIF(Notions!$B$2:$B$69,A19) -> 7 | C19: =IFERROR(AVERAGEIF(Notions!$B$2:$B$69,A19,Notions!$Q$2:$Q$69),0) -> 0.068181818 | D19: =COUNTIFS(Notions!$B$2:$B$69,A19,Notions!$R$2:$R$69,"Terminé") -> 0
A20: D8 – Périmètres et aires | B20: =COUNTIF(Notions!$B$2:$B$69,A20) -> 8 | C20: =IFERROR(AVERAGEIF(Notions!$B$2:$B$69,A20,Notions!$Q$2:$Q$69),0) -> 0.068181818 | D20: =COUNTIFS(Notions!$B$2:$B$69,A20,Notions!$R$2:$R$69,"Terminé") -> 0
A21: D9 – Géométrie dans l’espace | B21: =COUNTIF(Notions!$B$2:$B$69,A21) -> 3 | C21: =IFERROR(AVERAGEIF(Notions!$B$2:$B$69,A21,Notions!$Q$2:$Q$69),0) -> 0.068181818 | D21: =COUNTIFS(Notions!$B$2:$B$69,A21,Notions!$R$2:$R$69,"Terminé") -> 0
A22: D10 – Échelles et agrandissements | B22: =COUNTIF(Notions!$B$2:$B$69,A22) -> 4 | C22: =IFERROR(AVERAGEIF(Notions!$B$2:$B$69,A22,Notions!$Q$2:$Q$69),0) -> 0.068181818 | D22: =COUNTIFS(Notions!$B$2:$B$69,A22,Notions!$R$2:$R$69,"Terminé") -> 0
A23: D11 – Résolution de problèmes | B23: =COUNTIF(Notions!$B$2:$B$69,A23) -> 7 | C23: =IFERROR(AVERAGEIF(Notions!$B$2:$B$69,A23,Notions!$Q$2:$Q$69),0) -> 0.068181818 | D23: =COUNTIFS(Notions!$B$2:$B$69,A23,Notions!$R$2:$R$69,"Terminé") -> 0
A25: AVANCEMENT PAR VAGUE
A26: Vague | B26: Nb notions | C26: Avancement moyen | D26: Terminées
A27: V0 – Pilote | B27: =COUNTIF(Notions!$E$2:$E$69,A27) -> 1 | C27: =IFERROR(AVERAGEIF(Notions!$E$2:$E$69,A27,Notions!$Q$2:$Q$69),0) -> 0.34545455 | D27: =COUNTIFS(Notions!$E$2:$E$69,A27,Notions!$R$2:$R$69,"Terminé") -> 0
A28: MVP | B28: =COUNTIF(Notions!$E$2:$E$69,A28) -> 11 | C28: =IFERROR(AVERAGEIF(Notions!$E$2:$E$69,A28,Notions!$Q$2:$Q$69),0) -> 0.068181818 | D28: =COUNTIFS(Notions!$E$2:$E$69,A28,Notions!$R$2:$R$69,"Terminé") -> 0
A29: V1 | B29: =COUNTIF(Notions!$E$2:$E$69,A29) -> 14 | C29: =IFERROR(AVERAGEIF(Notions!$E$2:$E$69,A29,Notions!$Q$2:$Q$69),0) -> 0.068181818 | D29: =COUNTIFS(Notions!$E$2:$E$69,A29,Notions!$R$2:$R$69,"Terminé") -> 0
A30: V2 | B30: =COUNTIF(Notions!$E$2:$E$69,A30) -> 7 | C30: =IFERROR(AVERAGEIF(Notions!$E$2:$E$69,A30,Notions!$Q$2:$Q$69),0) -> 0.068181818 | D30: =COUNTIFS(Notions!$E$2:$E$69,A30,Notions!$R$2:$R$69,"Terminé") -> 0
A31: V3 | B31: =COUNTIF(Notions!$E$2:$E$69,A31) -> 24 | C31: =IFERROR(AVERAGEIF(Notions!$E$2:$E$69,A31,Notions!$Q$2:$Q$69),0) -> 0.068181818 | D31: =COUNTIFS(Notions!$E$2:$E$69,A31,Notions!$R$2:$R$69,"Terminé") -> 0
A32: V4 | B32: =COUNTIF(Notions!$E$2:$E$69,A32) -> 11 | C32: =IFERROR(AVERAGEIF(Notions!$E$2:$E$69,A32,Notions!$Q$2:$Q$69),0) -> 0.068181818 | D32: =COUNTIFS(Notions!$E$2:$E$69,A32,Notions!$R$2:$R$69,"Terminé") -> 0
A34: STATUT PAR TYPE DE LIVRABLE (68 notions)
A35: Livrable | B35: À faire | C35: En cours | D35: À valider | E35: Validé | F35: % validé
A36: Fiche de conception (doc maître) | B36: =COUNTIF(Notions!$F$2:$F$69,B$35) -> 0 | C36: =COUNTIF(Notions!$F$2:$F$69,C$35) -> 0 | D36: =COUNTIF(Notions!$F$2:$F$69,D$35) -> 68 | E36: =COUNTIF(Notions!$F$2:$F$69,E$35) -> 0 | F36: =E36/SUM(B36:E36) -> 0
A37: Validation référentiel (enseignants) | B37: =COUNTIF(Notions!$G$2:$G$69,B$35) -> 68 | C37: =COUNTIF(Notions!$G$2:$G$69,C$35) -> 0 | D37: =COUNTIF(Notions!$G$2:$G$69,D$35) -> 0 | E37: =COUNTIF(Notions!$G$2:$G$69,E$35) -> 0 | F37: =E37/SUM(B37:E37) -> 0
A38: Leçon rédigée (12 étapes) | B38: =COUNTIF(Notions!$H$2:$H$69,B$35) -> 67 | C38: =COUNTIF(Notions!$H$2:$H$69,C$35) -> 1 | D38: =COUNTIF(Notions!$H$2:$H$69,D$35) -> 0 | E38: =COUNTIF(Notions!$H$2:$H$69,E$35) -> 0 | F38: =E38/SUM(B38:E38) -> 0
A39: Script vidéo | B39: =COUNTIF(Notions!$I$2:$I$69,B$35) -> 67 | C39: =COUNTIF(Notions!$I$2:$I$69,C$35) -> 0 | D39: =COUNTIF(Notions!$I$2:$I$69,D$35) -> 1 | E39: =COUNTIF(Notions!$I$2:$I$69,E$35) -> 0 | F39: =E39/SUM(B39:E39) -> 0
A40: BD | B40: =COUNTIF(Notions!$J$2:$J$69,B$35) -> 67 | C40: =COUNTIF(Notions!$J$2:$J$69,C$35) -> 0 | D40: =COUNTIF(Notions!$J$2:$J$69,D$35) -> 1 | E40: =COUNTIF(Notions!$J$2:$J$69,E$35) -> 0 | F40: =E40/SUM(B40:E40) -> 0
A41: Jeu / manipulation | B41: =COUNTIF(Notions!$K$2:$K$69,B$35) -> 68 | C41: =COUNTIF(Notions!$K$2:$K$69,C$35) -> 0 | D41: =COUNTIF(Notions!$K$2:$K$69,D$35) -> 0 | E41: =COUNTIF(Notions!$K$2:$K$69,E$35) -> 0 | F41: =E41/SUM(B41:E41) -> 0
A42: Exercices A–E | B42: =COUNTIF(Notions!$L$2:$L$69,B$35) -> 67 | C42: =COUNTIF(Notions!$L$2:$L$69,C$35) -> 1 | D42: =COUNTIF(Notions!$L$2:$L$69,D$35) -> 0 | E42: =COUNTIF(Notions!$L$2:$L$69,E$35) -> 0 | F42: =E42/SUM(B42:E42) -> 0
A43: Problèmes P1–P4 | B43: =COUNTIF(Notions!$M$2:$M$69,B$35) -> 68 | C43: =COUNTIF(Notions!$M$2:$M$69,C$35) -> 0 | D43: =COUNTIF(Notions!$M$2:$M$69,D$35) -> 0 | E43: =COUNTIF(Notions!$M$2:$M$69,E$35) -> 0 | F43: =E43/SUM(B43:E43) -> 0
...

Sheet Lisez-moi
A1: FICHIER DE PILOTAGE – MATHO CM2
A2: Source : Projet_Matho_CM2_Benin_Document_Maitre.docx (version 1.0, septembre 2026).
A4: COMMENT L’UTILISER
A5: 1. Les cellules à fond jaune et texte bleu sont à modifier (statuts, responsables, dates, notes). Les autres cellules sont des formules : ne les écrasez pas.
A6: 2. Feuille « Notions » : une ligne par notion, 11 livrables suivis. Choisissez un statut dans la liste : À faire, En cours, À valider, Validé.
A7: 3. L’avancement % et l’état global se calculent tout seuls, avec les poids de la feuille « Paramètres ».
A8: 4. Feuille « Tableau de bord » : synthèse globale, par domaine, par vague et par livrable.
A9: 5b. Feuille « Budget API » : suivi des dépenses Claude (budget de 10 € au total), avec seuils d’alerte et statut affiché sur le tableau de bord.
A10: 5c. Feuilles « Revue documentaire » et « Principes de conception » : sources de recherche et règles de conception qui en découlent.
A11: 5. Feuilles « Livrables », « Phasage » et « Journal » : suivi des livrables finaux, des 12 phases, des décisions, actions et questions ouvertes.
A13: PROTOCOLE DE SESSION AVEC CLAUDE
A14: Claude ne garde pas la mémoire d’une conversation à l’autre. Au début de chaque session : envoyez ce fichier à jour et indiquez l’objectif de la session (par exemple « produire la leçon N22 »). À la fin de la session, demandez une mise à jour du fichier.
... A19: • Le découpage en vagues (V0 à V4) est une hypothèse de l’assistant, modifiable dans la colonne « Vague ».

Sheet Notions
A1: Code | B1: Domaine | C1: Notion | D1: Prérequis (doc maître) | E1: Vague | F1: Fiche de conception (doc maître) | G1: Validation référentiel (enseignants) | H1: Leçon rédigée (12 étapes) | I1: Script vidéo | J1: BD | K1: Jeu / manipulation | L1: Exercices A–E | M1: Problèmes P1–P4 | N1: QCM CEP | O1: Corrections & remédiation | P1: Contrôle qualité (maths + test enfant) | Q1: Avancement % | R1: État global | S1: Responsable | T1: Dernière MAJ | U1: Notes
A2: N01 | B2: D1 – Numération | C2: Lire et écrire les grands nombres | D2: valeur de position; lecture des nombres usuels | E2: V1 | F2: À valider | G2: À faire | H2: À faire | I2: À faire | J2: À faire | K2: À faire | L2: À faire | M2: À faire | N2: À faire | O2: À faire | P2: À faire | Q2: =(COUNTIF(F2:P2,Paramètres!$A$7)*Paramètres!$B$7+COUNTIF(F2:P2,Paramètres!$A$6)*Paramètres!$B$6+COUNTIF(F2:P2,Paramètres!$A$5)*Paramètres!$B$5)/COLUMNS(F2:P2) -> 0.068181818 | R2: =IF(Q2>=1,"Terminé",IF(COUNTIF(H2:P2,Paramètres!$A$4)=9,"Non démarré","En cours")) -> Non démarré
A3: N02 | B3: D1 – Numération | C3: Comparer et ranger les nombres | D3: valeur de position; lecture des nombres usuels | E3: V1 | F3: À valider | G3: À faire | H3: À faire | I3: À faire | J3: À faire | K3: À faire | L3: À faire | M3: À faire | N3: À faire | O3: À faire | P3: À faire | Q3: =(COUNTIF(F3:P3,Paramètres!$A$7)*Paramètres!$B$7+COUNTIF(F3:P3,Paramètres!$A$6)*Paramètres!$B$6+COUNTIF(F3:P3,Paramètres!$A$5)*Paramètres!$B$5)/COLUMNS(F3:P3) -> 0.068181818 | R3: =IF(Q3>=1,"Terminé",IF(COUNTIF(H3:P3,Paramètres!$A$4)=9,"Non démarré","En cours")) -> Non démarré
A4: N03 | B4: D1 – Numération | C4: Décomposer et recomposer les nombres | D4: valeur de position; lecture des nombres usuels | E4: V1 | F4: À valider | G4: À faire | H4: À faire | I4: À faire | J4: À faire | K4: À faire | L4: À faire | M4: À faire | N4: À faire | O4: À faire | P4: À faire | Q4: =(COUNTIF(F4:P4,Paramètres!$A$7)*Paramètres!$B$7+COUNTIF(F4:P4,Paramètres!$A$6)*Paramètres!$B$6+COUNTIF(F4:P4,Paramètres!$A$5)*Paramètres!$B$5)/COLUMNS(F4:P4) -> 0.068181818 | R4: =IF(Q4>=1,"Terminé",IF(COUNTIF(H4:P4,Paramètres!$A$4)=9,"Non démarré","En cours")) -> Non démarré
A5: N04 | B5: D2 – Nombres décimaux | C5: Comprendre les nombres décimaux | D5: numération entière; valeur de position | E5: V1 | F5: À valider | G5: À faire | H5: À faire | I5: À faire | J5: À faire | K5: À faire | L5: À faire | M5: À faire | N5: À faire | O5: À faire | P5: À faire | Q5: =(COUNTIF(F5:P5,Paramètres!$A$7)*Paramètres!$B$7+COUNTIF(F5:P5,Paramètres!$A$6)*Paramètres!$B$6+COUNTIF(F5:P5,Paramètres!$A$5)*Paramètres!$B$5)/COLUMNS(F5:P5) -> 0.068181818 | R5: =IF(Q5>=1,"Terminé",IF(COUNTIF(H5:P5,Paramètres!$A$4)=9,"Non démarré","En cours")) -> Non démarré
A6: N05 | B6: D2 – Nombres décimaux | C6: Lire et écrire les nombres décimaux | D6: numération entière; valeur de position | E6: V1 | F6: À valider | G6: À faire | H6: À faire | I6: À faire | J6: À faire | K6: À faire | L6: À faire | M6: À faire | N6: À faire | O6: À faire | P6: À faire | Q6: =(COUNTIF(F6:P6,Paramètres!$A$7)*Paramètres!$B$7+COUNTIF(F6:P6,Paramètres!$A$6)*Paramètres!$B$6+COUNTIF(F6:P6,Paramètres!$A$5)*Paramètres!$B$5)/COLUMNS(F6:P6) -> 0.068181818 | R6: =IF(Q6>=1,"Terminé",IF(COUNTIF(H6:P6,Paramètres!$A$4)=9,"Non démarré","En cours")) -> Non démarré
A7: N06 | B7: D2 – Nombres décimaux | C7: Comparer les nombres décimaux | D7: numération entière; valeur de position | E7: V1 | F7: À valider | G7: À faire | H7: À faire | I7: À faire | J7: À faire | K7: À faire | L7: À faire | M7: À faire | N7: À faire | O7: À faire | P7: À faire | Q7: =(COUNTIF(F7:P7,Paramètres!$A$7)*Paramètres!$B$7+COUNTIF(F7:P7,Paramètres!$A$6)*Paramètres!$B$6+COUNTIF(F7:P7,Paramètres!$A$5)*Paramètres!$B$5)/COLUMNS(F7:P7) -> 0.068181818 | R7: =IF(Q7>=1,"Terminé",IF(COUNTIF(H7:P7,Paramètres!$A$4)=9,"Non démarré","En cours")) -> Non démarré
A8: N07 | B8: D2 – Nombres décimaux | C8: Ranger les nombres décimaux | D8: numération entière; valeur de position | E8: V1 | F8: À valider | G8: À faire | H8: À faire | I8: À faire | J8: À faire | K8: À faire | L8: À faire | M8: À faire | N8: À faire | O8: À faire | P8: À faire | Q8: =(COUNTIF(F8:P8,Paramètres!$A$7)*Paramètres!$B$7+COUNTIF(F8:P8,Paramètres!$A$6)*Paramètres!$B$6+COUNTIF(F8:P8,Paramètres!$A$5)*Paramètres!$B$5)/COLUMNS(F8:P8) -> 0.068181818 | R8: =IF(Q8>=1,"Terminé",IF(COUNTIF(H8:P8,Paramètres!$A$4)=9,"Non démarré","En cours")) -> Non démarré
A9: N08 | B9: D3 – Calcul | C9: Additionner des entiers | D9: numération; tables de multiplication; sens des quatre opérations | E9: V1 | F9: À valider | G9: À faire | H9: À faire | I9: À faire | J9: À faire | K9: À faire | L9: À faire | M9: À faire | N9: À faire | O9: À faire | P9: À faire | Q9: =(COUNTIF(F9:P9,Paramètres!$A$7)*Paramètres!$B$7+COUNTIF(F9:P9,Paramètres!$A$6)*Paramètres!$B$6+COUNTIF(F9:P9,Paramètres!$A$5)*Paramètres!$B$5)/COLUMNS(F9:P9) -> 0.068181818 | R9: =IF(Q9>=1,"Terminé",IF(COUNTIF(H9:P9,Paramètres!$A$4)=9,"Non démarré","En cours")) -> Non démarré
A10: N09 | B10: D3 – Calcul | C10: Soustraire des entiers | D10: numération; tables de multiplication; sens des quatre opérations | E10: V1 | F10: À valider | G10: À faire | H10: À faire | I10: À faire | J10: À faire | K10: À faire | L10: À faire | M10: À faire | N10: À faire | O10: À faire | P10: À faire | Q10: =(COUNTIF(F10:P10,Paramètres!$A$7)*Paramètres!$B$7+COUNTIF(F10:P10,Paramètres!$A$6)*Paramètres!$B$6+COUNTIF(F10:P10,Paramètres!$A$5)*Paramètres!$B$5)/COLUMNS(F10:P10) -> 0.068181818 | R10: =IF(Q10>=1,"Terminé",IF(COUNTIF(H10:P10,Paramètres!$A$4)=9,"Non démarré","En cours")) -> Non démarré
A11: N10 | B11: D3 – Calcul | C11: Multiplier des entiers | D11: numération; tables de multiplication; sens des quatre opérations | E11: MVP | F11: À valider | G11: À faire | H11: À faire | I11: À faire | J11: À faire | K11: À faire | L11: À faire | M11: À faire | N11: À faire | O11: À faire | P11: À faire | Q11: =(COUNTIF(F11:P11,Paramètres!$A$7)*Paramètres!$B$7+COUNTIF(F11:P11,Paramètres!$A$6)*Paramètres!$B$6+COUNTIF(F11:P11,Paramètres!$A$5)*Paramètres!$B$5)/COLUMNS(F11:P11) -> 0.068181818 | R11: =IF(Q11>=1,"Terminé",IF(COUNTIF(H11:P11,Paramètres!$A$4)=9,"Non démarré","En cours")) -> Non démarré
A12: N11 | B12: D3 – Calcul | C12: Diviser des entiers | D12: numération; tables de multiplication; sens des quatre opérations | E12: MVP | F12: À valider | G12: À faire | H12: À faire | I12: À faire | J12: À faire | K12: À faire | L12: À faire | M12: À faire | N12: À faire | O12: À faire | P12: À faire | Q12: =(COUNTIF(F12:P12,Paramètres!$A$7)*Paramètres!$B$7+COUNTIF(F12:P12,Paramètres!$A$6)*Paramètres!$B$6+COUNTIF(F12:P12,Paramètres!$A$5)*Paramètres!$B$5)/COLUMNS(F12:P12) -> 0.068181818 | R12: =IF(Q12>=1,"Terminé",IF(COUNTIF(H12:P12,Paramètres!$A$4)=9,"Non démarré","En cours")) -> Non démarré
A13: N12 | B13: D3 – Calcul | C13: Additionner des décimaux | D13: numération; tables de multiplication; sens des quatre opérations | E13: V1 | F13: À valider | G13: À faire | H13: À faire | I13: À faire | J13: À faire | K13: À faire | L13: À faire | M13: À faire | N13: À faire | O13: À faire | P13: À faire | Q13: =(COUNTIF(F13:P13,Paramètres!$A$7)*Paramètres!$B$7+COUNTIF(F13:P13,Paramètres!$A$6)*Paramètres!$B$6+COUNTIF(F13:P13,Paramètres!$A$5)*Paramètres!$B$5)/COLUMNS(F13:P13) -> 0.068181818 | R13: =IF(Q13>=1,"Terminé",IF(COUNTIF(H13:P13,Paramètres!$A$4)=9,"Non démarré","En cours")) -> Non démarré
... A22: N21 | B22: D4 – Fractions | C22: Fractions équivalentes | D22: partage en parts égales; division simple | E22: MVP | F22: À valider | G22: À faire | H22: À faire | I22: À faire | J22: À faire | K22: À faire | L22: À faire | M22: À faire | N22: À faire | O22: À faire | P22: À faire | Q22: =(COUNTIF(F22:P22,Paramètres!$A$7)*Paramètres!$B$7+COUNTIF(F22:P22,Paramètres!$A$6)*Paramètres!$B$6+COUNTIF(F22:P22,Paramètres!$A$5)*Paramètres!$B$5)/COLUMNS(F22:P22) -> 0.068181818 | R22: =IF(Q22>=1,"Terminé",IF(COUNTIF(H22:P22,Paramètres!$A$4)=9,"Non démarré","En cours")) -> Non démarré
A23: N22 | B23: D4 – Fractions | C23: Prendre une fraction d’une quantité | D23: partage en parts égales; division simple | E23: V0 – Pilote | F23: À valider | G23: À faire | H23: En cours | I23: À valider | J23: À valider | K23: À faire | L23: En cours | M23: À faire | N23: À faire | O23: À valider | P23: À faire | Q23: =(COUNTIF(F23:P23,Paramètres!$A$7)*Paramètres!$B$7+COUNTIF(F23:P23,Paramètres!$A$6)*Paramètres!$B$6+COUNTIF(F23:P23,Paramètres!$A$5)*Paramètres!$B$5)/COLUMNS(F23:P23) -> 0.34545455 | R23: =IF(Q23>=1,"Terminé",IF(COUNTIF(H23:P23,Paramètres!$A$4)=9,"Non démarré","En cours")) -> En cours | T23: 2026-09-29 | U23: Notion pilote. Scénario pilote v0.1 rédigé (mission, défi, vidéo, BD, textes de Mathéo, quiz, boss) : à valider par un enseignant et à tester avec des enfants.
A24: N23 | B24: D4 – Fractions | C24: Résoudre des problèmes avec des fractions | D24: partage en parts égales; division simple | E24: MVP | F24: À valider | G24: À faire | H24: À faire | I24: À faire | J24: À faire | K24: À faire | L24: À faire | M24: À faire | N24: À faire | O24: À faire | P24: À faire | Q24: =(COUNTIF(F24:P24,Paramètres!$A$7)*Paramètres!$B$7+COUNTIF(F24:P24,Paramètres!$A$6)*Paramètres!$B$6+COUNTIF(F24:P24,Paramètres!$A$5)*Paramètres!$B$5)/COLUMNS(F24:P24) -> 0.068181818 | R24: =IF(Q24>=1,"Terminé",IF(COUNTIF(H24:P24,Paramètres!$A$4)=9,"Non démarré","En cours")) -> Non démarré
A25: N24 | B25: D5 – Proportionnalité | C25: Reconnaître une situation proportionnelle | D25: multiplication et division; fractions simples | E25: V2 | F25: À valider | G25: À faire | H25: À faire | I25: À faire | J25: À faire | K25: À faire | L25: À faire | M25: À faire | N25: À faire | O25: À faire | P25: À faire | Q25: =(COUNTIF(F25:P25,Paramètres!$A$7)*Paramètres!$B$7+COUNTIF(F25:P25,Paramètres!$A$6)*Paramètres!$B$6+COUNTIF(F25:P25,Paramètres!$A$5)*Paramètres!$B$5)/COLUMNS(F25:P25) -> 0.068181818 | R25: =IF(Q25>=1,"Terminé",IF(COUNTIF(H25:P25,Paramètres!$A$4)=9,"Non démarré","En cours")) -> Non démarré
A26: N25 | B26: D5 – Proportionnalité | C26: Tableau de proportionnalité | D26: multiplication et division; fractions simples | E26: V2 | F26: À valider | G26: À faire | H26: À faire | I26: À faire | J26: À faire | K26: À faire | L26: À faire | M26: À faire | N26: À faire | O26: À faire | P26: À faire | Q26: =(COUNTIF(F26:P26,Paramètres!$A$7)*Paramètres!$B$7+COUNTIF(F26:P26,Paramètres!$A$6)*Paramètres!$B$6+COUNTIF(F26:P26,Paramètres!$A$5)*Paramètres!$B$5)/COLUMNS(F26:P26) -> 0.068181818 | R26: =IF(Q26>=1,"Terminé",IF(COUNTIF(H26:P26,Paramètres!$A$4)=9,"Non démarré","En cours")) -> Non démarré
A27: N26 | B27: D5 – Proportionnalité | C27: Règle de trois | D27: multiplication et division; fractions simples | E27: V2 | F27: À valider | G27: À faire | H27: À faire | I27: À faire | J27: À faire | K27: À faire | L27: À faire | M27: À faire | N27: À faire | O27: À faire | P27: À faire | Q27: =(COUNTIF(F27:P27,Paramètres!$A$7)*Paramètres!$B$7+COUNTIF(F27:P27,Paramètres!$A$6)*Paramètres!$B$6+COUNTIF(F27:P27,Paramètres!$A$5)*Paramètres!$B$5)/COLUMNS(F27:P27) -> 0.068181818 | R27: =IF(Q27>=1,"Terminé",IF(COUNTIF(H27:P27,Paramètres!$A$4)=9,"Non démarré","En cours")) -> Non démarré
A28: N27 | B28: D5 – Proportionnalité | C28: Partages proportionnels | D28: multiplication et division; fractions simples | E28: V2 | F28: À valider | G28: À faire | H28: À faire | I28: À faire | J28: À faire | K28: À faire | L28: À faire | M28: À faire | N28: À faire | O28: À faire | P28: À faire | Q28: =(COUNTIF(F28:P28,Paramètres!$A$7)*Paramètres!$B$7+COUNTIF(F28:P28,Paramètres!$A$6)*Paramètres!$B$6+COUNTIF(F28:P28,Paramètres!$A$5)*Paramètres!$B$5)/COLUMNS(F28:P28) -> 0.068181818 | R28: =IF(Q28>=1,"Terminé",IF(COUNTIF(H28:P28,Paramètres!$A$4)=9,"Non démarré","En cours")) -> Non démarré
A29: N28 | B29: D5 – Proportionnalité | C29: Pourcentages | D29: multiplication et division; fractions simples | E29: V2 | F29: À valider | G29: À faire | H29: À faire | I29: À faire | J29: À faire | K29: À faire | L29: À faire | M29: À faire | N29: À faire | O29: À faire | P29: À faire | Q29: =(COUNTIF(F29:P29,Paramètres!$A$7)*Paramètres!$B$7+COUNTIF(F29:P29,Paramètres!$A$6)*Paramètres!$B$6+COUNTIF(F29:P29,Paramètres!$A$5)*Paramètres!$B$5)/COLUMNS(F29:P29) -> 0.068181818 | R29: =IF(Q29>=1,"Terminé",IF(COUNTIF(H29:P29,Paramètres!$A$4)=9,"Non démarré","En cours")) -> Non démarré
A30: N29 | B30: D5 – Proportionnalité | C30: Augmentations et réductions | D30: multiplication et division; fractions simples | E30: V2 | F30: À valider | G30: À faire | H30: À faire | I30: À faire | J30: À faire | K30: À faire | L30: À faire | M30: À faire | N30: À faire | O30: À faire | P30: À faire | Q30: =(COUNTIF(F30:P30,Paramètres!$A$7)*Paramètres!$B$7+COUNTIF(F30:P30,Paramètres!$A$6)*Paramètres!$B$6+COUNTIF(F30:P30,Paramètres!$A$5)*Paramètres!$B$5)/COLUMNS(F30:P30) -> 0.068181818 | R30: =IF(Q30>=1,"Terminé",IF(COUNTIF(H30:P30,Paramètres!$A$4)=9,"Non démarré","En cours")) -> Non démarré
A31: N30 | B31: D5 – Proportionnalité | C31: Problèmes de proportionnalité | D31: multiplication et division; fractions simples | E31: V2 | F31: À valider | G31: À faire | H31: À faire | I31: À faire | J31: À faire | K31: À faire | L31: À faire | M31: À faire | N31: À faire | O31: À faire | P31: À faire | Q31: =(COUNTIF(F31:P31,Paramètres!$A$7)*Paramètres!$B$7+COUNTIF(F31:P31,Paramètres!$A$6)*Paramètres!$B$6+COUNTIF(F31:P31,Paramètres!$A$5)*Paramètres!$B$5)/COLUMNS(F31:P31) -> 0.068181818 | R31: =IF(Q31>=1,"Terminé",IF(COUNTIF(H31:P31,Paramètres!$A$4)=9,"Non démarré","En cours")) -> Non démarré
A32: N31 | B32: D6 – Grandeurs et mesures | C32: Longueurs | D32: lecture des unités; comparaison de grandeurs | E32: V3 | F32: À valider | G32: À faire | H32: À faire | I32: À faire | J32: À faire | K32: À faire | L32: À faire | M32: À faire | N32: À faire | O32: À faire | P32: À faire | Q32: =(COUNTIF(F32:P32,Paramètres!$A$7)*Paramètres!$B$7+COUNTIF(F32:P32,Paramètres!$A$6)*Paramètres!$B$6+COUNTIF(F32:P32,Paramètres!$A$5)*Paramètres!$B$5)/COLUMNS(F32:P32) -> 0.068181818 | R32: =IF(Q32>=1,"Terminé",IF(COUNTIF(H32:P32,Paramètres!$A$4)=9,"Non démarré","En cours")) -> Non démarré
A33: N32 | B33: D6 – Grandeurs et mesures | C33: Conversion des longueurs | D33: lecture des unités; comparaison de grandeurs | E33: V3 | F33: À valider | G33: À faire | H33: À faire | I33: À faire | J33: À faire | K33: À faire | L33: À faire | M33: À faire | N33: À faire | O33: À faire | P33: À faire | Q33: =(COUNTIF(F33:P33,Paramètres!$A$7)*Paramètres!$B$7+COUNTIF(F33:P33,Paramètres!$A$6)*Paramètres!$B$6+COUNTIF(F33:P33,Paramètres!$A$5)*Paramètres!$B$5)/COLUMNS(F33:P33) -> 0.068181818 | R33: =IF(Q33>=1,"Terminé",IF(COUNTIF(H33:P33,Paramètres!$A$4)=9,"Non démarré","En cours")) -> Non démarré
A34: N33 | B34: D6 – Grandeurs et mesures | C34: Calculs avec les longueurs | D34: lecture des unités; comparaison de grandeurs | E34: V3 | F34: À valider | G34: À faire | H34: À faire | I34: À faire | J34: À faire | K34: À faire | L34: À faire | M34: À faire | N34: À faire | O34: À faire | P34: À faire | Q34: =(COUNTIF(F34:P34,Paramètres!$A$7)*Paramètres!$B$7+COUNTIF(F34:P34,Paramètres!$A$6)*Paramètres!$B$6+COUNTIF(F34:P34,Paramètres!$A$5)*Paramètres!$B$5)/COLUMNS(F34:P34) -> 0.068181818 | R34: =IF(Q34>=1,"Terminé",IF(COUNTIF(H34:P34,Paramètres!$A$4)=9,"Non démarré","En cours")) -> Non démarré
A35: N34 | B35: D6 – Grandeurs et mesures | C35: Masses | D35: lecture des unités; comparaison de grandeurs | E35: V3 | F35: À valider | G35: À faire | H35: À faire | I35: À faire | J35: À faire | K35: À faire | L35: À faire | M35: À faire | N35: À faire | O35: À faire | P35: À faire | Q35: =(COUNTIF(F35:P35,Paramètres!$A$7)*Paramètres!$B$7+COUNTIF(F35:P35,Paramètres!$A$6)*Paramètres!$B$6+COUNTIF(F35:P35,Paramètres!$A$5)*Paramètres!$B$5)/COLUMNS(F35:P35) -> 0.068181818 | R35: =IF(Q35>=1,"Terminé",IF(COUNTIF(H35:P35,Paramètres!$A$4)=9,"Non démarré","En cours")) -> Non démarré
... A69: N68 | B69: D11 – Résolution de problèmes | C69: Résoudre un problème à plusieurs opérations | D69: lecture de consignes; opérations étudiées | E69: V4 | F69: À valider | G69: À faire | H69: À faire | I69: À faire | J69: À faire | K69: À faire | L69: À faire | M69: À faire | N69: À faire | O69: À faire | P69: À faire | Q69: =(COUNTIF(F69:P69,Paramètres!$A$7)*Paramètres!$B$7+COUNTIF(F69:P69,Paramètres!$A$6)*Paramètres!$B$6+COUNTIF(F69:P69,Paramètres!$A$5)*Paramètres!$B$5)/COLUMNS(F69:P69) -> 0.068181818 | R69: =IF(Q69>=1,"Terminé",IF(COUNTIF(H69:P69,Paramètres!$A$4)=9,"Non démarré","En cours")) -> Non démarré

Sheet Livrables
A1: Livrable (section 24 du doc maître) | B1: Phase | C1: Type | D1: Statut | E1: Responsable | F1: Échéance | G1: Notes
A2: Référentiel CM2 structuré et validé | B2: 1 – Référentiel | C2: Contenu | D2: À faire
A3: Matrice compétences / sous-compétences | B3: 1 – Référentiel | C3: Contenu | D3: À faire
A4: 68 fiches pédagogiques complètes | B4: 2 – Fiches | C4: Contenu | D4: À faire
A5: Bibliothèque de scripts vidéo | B5: 2 – Fiches | C5: Contenu | D5: À faire
A6: Bibliothèque de storyboards | B6: 2 – Fiches | C6: Contenu | D6: À faire
A7: Bibliothèque de BD | B7: 2 – Fiches | C7: Contenu | D7: À faire
A8: Bibliothèque de jeux/manipulations | B8: 2 – Fiches | C8: Contenu | D8: À faire
A9: Banque d’exercices A–E | B9: 2 – Fiches | C9: Contenu | D9: À faire
A10: Banque de problèmes | B10: 2 – Fiches | C10: Contenu | D10: À faire
A11: Matrice erreurs / remédiations | B11: 2 – Fiches | C11: Contenu | D11: À faire
A12: Banque QCM CEP | B12: 3 – CEP | C12: Contenu | D12: À faire
A13: Banque d’épreuves CEP | B13: 3 – CEP | C13: Contenu | D13: À faire
A14: Simulateur CEP | B14: 3 – CEP | C14: Contenu | D14: À faire
A15: Cahier des charges du tuteur IA | B15: 5 – MVP | C15: Produit / technique | D15: À faire | G15: Base : section 13 du doc maître.
A16: Design system UX/UI | B16: 4 – UX/UI | C16: Produit / technique | D16: À faire
A17: Application mobile | B17: 7 – Développement | C17: Produit / technique | D17: À faire
A18: Backend et modèle de données | B18: 7 – Développement | C18: Produit / technique | D18: À faire
A19: Dashboards élève/parent/enseignant | B19: 7 – Développement | C19: Produit / technique | D19: À faire
A20: Système analytics | B20: 7 – Développement | C20: Produit / technique | D20: À faire
A21: Dossier QA | B21: 6 – Tests | C21: Produit / technique | D21: À faire
A22: Guide d’administration | B22: 11 – Déploiement | C22: Contenu | D22: À faire
A23: Guide enseignant | B23: 11 – Déploiement | C23: Contenu | D23: À faire
A24: Guide parent | B24: 11 – Déploiement | C24: Contenu | D24: À faire
A25: Rapport pilote | B25: 8 – Pilote | C25: Suivi | D25: À faire
A26: Rapport d’évaluation et recommandations | B26: 9 – Évaluation | C26: Suivi | D26: À faire

Sheet Phasage
A1: N° | B1: Phase | C1: Repère de planification (doc maître) | D1: Sortie attendue | E1: Statut | F1: Début | G1: Fin | H1: Notes
A2: 0 | B2: Cadrage | C2: 2–4 semaines | D2: Vision, périmètre, gouvernance, critères de réussite. | E2: En cours | H2: Document maître v1.0 reçu (sept. 2026). Pilotage lancé.
A3: 1 | B3: Référentiel | C3: 6–10 semaines | D3: Validation des notions, compétences, prérequis, progression. | E3: À faire
A4: 2 | B4: Fiches pédagogiques | C4: 3–6 mois | D4: Production détaillée des 68 notions, en vagues. | E4: À faire
A5: 3 | B5: CEP en parallèle | C5: En parallèle | D5: Vidéos, QCM, problèmes, sujets, simulateur. | E5: À faire
A6: 4 | B6: UX/UI | C6: En parallèle | D6: Prototype, tests de navigation, design system. | E6: À faire
A7: 5 | B7: MVP | C7: Cycle court | D7: 5–10 leçons représentatives + IA + suivi. | E7: À faire
A8: 6 | B8: Tests utilisateurs | C8: Plusieurs vagues | D8: Enfants, enseignants, parents ; corrections. | E8: À faire
A9: 7 | B9: Développement complet | C9: Après validation MVP | D9: Toutes les fonctions, offline, dashboards. | E9: À faire
A10: 8 | B10: Pilote | C10: Établissements ciblés | D10: Mesure des usages et apprentissages. | E10: À faire
A11: 9 | B11: Évaluation | C11: Après pilote | D11: Analyse d’impact, qualité, adoption. | E11: À faire
A12: 10 | B12: Amélioration | C12: Itératif | D12: Corrections et enrichissements. | E12: À faire
A13: 11 | B13: Déploiement | C13: Progressif | D13: Montée en charge, formation, accompagnement. | E13: À faire

Sheet Journal
A1: Date | B1: Type | C1: Description | D1: Responsable | E1: Échéance | F1: Statut
A2: 2026-09-29 | B2: Décision | C2: Le projet est piloté par vagues (V0 pilote N22, puis V1 à V4) ; découpage à confirmer. | D2: Assistant / Porteur du projet | F2: En cours
A3: 2026-09-29 | B3: Décision | C3: Produire d’abord une tranche verticale complète sur N22 (leçon, exercices, corrections, script vidéo, BD, prototype). | D3: Assistant / Porteur du projet | F3: À faire
A4: 2026-09-29 | B4: Action | C4: Prompt maître de BD pour le chapitre Fractions (N17–N23) créé ; à utiliser avec l’épisode N22. | D4: Assistant | F4: Terminé
A5: 2026-09-29 | B5: Action | C5: Rédiger la leçon N22 complète (12 étapes) à partir de la section 10 du doc maître. | D5: Assistant | F5: À faire
A6: 2026-09-29 | B6: Question ouverte | C6: Qui valide le référentiel de 68 notions côté enseignants/experts béninois, et à quelle date ? | D6: Porteur du projet | F6: À faire
A7: 2026-09-29 | B7: Question ouverte | C7: Quels programmes officiels béninois en vigueur servent de référence pour la validation ? | D7: Porteur du projet | F7: À faire
A8: 2026-09-29 | B8: Question ouverte | C8: Outils retenus pour voix, vidéo et illustrations (génération d’images, montage) ? | D8: Porteur du projet | F8: À faire
A9: 2026-09-30 | B9: Décision | C9: Texte : Laguna en modèle principal, DeepSeek en repli automatique (hermes fallback ; clé DEEPSEEK_API_KEY dans le fichier .env du VPS). Usage ponctuel pour ne pas perdre une opération en cours. | D9: Porteur du projet | F9: Terminé
A10: 2026-09-30 | B10: Décision | C10: Vision (images et vidéos, lecture seule) : Qwen3-VL en principal, Gemini Flash en repli via auxiliary.vision. La création d’images reste dans Midjourney, Blender et Canva. | D10: Porteur du projet | F10: Terminé
A11: 2026-09-30 | B11: Décision | C11: Relecteur : Claude via clé d’API officielle dans Hermes. Budget maximal 10 € au total, crédits prépayés, sans rechargement automatique. Voir feuille « Budget API ». | D11: Porteur du projet | F11: Terminé
A12: 2026-09-30 | B12: Décision | C12: Aucun routeur tiers (OmniRoute, 9Router) sur le VPS. Repli par les fournisseurs officiels via Hermes. | D12: Porteur du projet | F12: Terminé
A13: 2026-09-30 | B13: Décision | C13: Application web (PWA) à la place de Godot ; voix pré-générées ; Blender limité à la mascotte et à quelques décors. | D13: Porteur du projet | F13: Terminé
... A48: 2026-09-30 | B48: Action | C48: Déposer les documents de référence dans le dépôt Git privé et donner à Hermes le message d’amorce pour lancer la mission M0. | D48: Porteur du projet | F48: À faire

Sheet Budget API
A1: BUDGET API CLAUDE – SUIVI DE LA CONSOMMATION
A2: Cellules jaunes à fond bleu : à modifier. Le reste se calcule. Ne jamais écrire de clé d’API dans ce fichier.
A3: Paramètre | B3: Valeur | C3: Note
A4: Budget total du projet (€) | B4: 10 | C4: Décision du porteur du projet (30/09/2026).
A5: Taux de change ($ pour 1 €) | B5: 1.1 | C5: Hypothèse : à mettre à jour avec le taux du jour.
A6: Seuil « vigilance » | B6: 0.5 | C6: Au-delà : relectures par lots (Batch, −50 %).
A7: Seuil « critiques seulement » | B7: 0.8 | C7: Au-delà : seuls les livrables critiques sont relus par Claude.
A8: Seuil « arrêt total » | B8: 1 | C8: Arrêt de tout appel Claude jusqu’à décision du porteur.
A9: Tokens d’entrée d’une relecture type | B9: 15000 | C9: Hypothèse de l’assistant (livrable + grille + extraits).
A10: Tokens de sortie d’une relecture type | B10: 1500 | C10: Hypothèse de l’assistant (verdict + corrections).
A12: TARIFS (dollars par million de tokens)
A13: Modèle | B13: Identifiant API | C13: Entrée ($/M) | D13: Sortie ($/M) | E13: Note
A14: Haiku 4.5 | B14: claude-haiku-4-5-20251001 | C14: 1 | D14: 5 | E14: Sources publiques, sept. 2026.
A15: Sonnet 5.5 | B15: claude-sonnet-5-5 | C15: 2 | D15: 10 | E15: Tarif de Sonnet 5 utilisé par défaut : à vérifier dans la Console pour la version 5.5.
A16: Opus 5.5 | B16: claude-opus-5-5 | C16: 4 | D16: 20 | E16: Sources publiques, sept. 2026 (lancé le 22/09/2026).
A17: Le cache (−90 % sur les tokens relus) et l’API par lots (−50 %) ne sont pas modélisés : les coûts calculés sont donc des estimations prudentes (plutôt supérieures).
A19: SYNTHÈSE
A20: Dépensé (€) | B20: =SUM(G34:G233) -> 0
A21: Reste (€) | B21: =B4-B20 -> 10
A22: Consommation du budget | B22: =IF(B4=0,0,B20/B4) -> 0
A23: Statut | B23: =IF(B22>=B8,"ARRÊT TOTAL – attendre la décision du porteur",IF(B22>=B7,"CRITIQUES SEULEMENT",IF(B22>=B6,"VIGILANCE – lots (Batch)","NORMAL"))) -> NORMAL
A24: Nombre d’appels journalisés | B24: =COUNT(D34:D233) -> 0
A25: Coût type d’une relecture Sonnet ($) | B25: =(B9*C15+B10*D15)/1000000 -> 0.045
A26: Relectures Sonnet restantes (estimation) | B26: =IF(B25=0,0,ROUNDDOWN(MAX(0,B21)*B5/B25,0)) -> 244
A27: Coût moyen par appel (€) | B27: =IF(B24=0,"",B20/B24)
A29: JOURNAL DES APPELS (une ligne par appel ou par lot)
A30: Exemple de saisie (non compté) : 2026-09-30 | Sonnet 5.5 | N22 – leçon | 15000 | 1500 → environ 0,05 $.
A31: Hermes journalise chaque appel Claude (date, modèle, tokens, tâche) ; recopiez ou faites remplir ces lignes automatiquement.
A33: Date | B33: Modèle | C33: Livrable / tâche | D33: Tokens entrée | E33: Tokens sortie | F33: Coût ($) | G33: Coût (€) | H33: Cumul (€) | I33: Notes
F34: =IF(OR(D34="",E34=""),"",IFERROR((D34*INDEX($C$14:$C$16,MATCH(B34,$A$14:$A$16,0))+E34*INDEX($D$14:$D$16,MATCH(B34,$A$14:$A$16,0)))/1000000,"")) | G34: =IF(F34="","",F34/$B$5) | H34: =IF(G34="","",SUM($G$34:G34))
F35: =IF(OR(D35="",E35=""),"",IFERROR((D35*INDEX($C$14:$C$16,MATCH(B35,$A$14:$A$16,0))+E35*INDEX($D$14:$D$16,MATCH(B35,$A$14:$A$16,0)))/1000000,"")) | G35: =IF(F35="","",F35/$B$5) | H35: =IF(G35="","",SUM($G$34:G35))
F36: =IF(OR(D36="",E36=""),"",IFERROR((D36*INDEX($C$14:$C$16,MATCH(B36,$A$14:$A$16,0))+E36*INDEX($D$14:$D$16,MATCH(B36,$A$14:$A$16,0)))/1000000,"")) | G36: =IF(F36="","",F36/$B$5) | H36: =IF(G36="","",SUM($G$34:G36))
F37: =IF(OR(D37="",E37=""),"",IFERROR((D37*INDEX($C$14:$C$16,MATCH(B37,$A$14:$A$16,0))+E37*INDEX($D$14:$D$16,MATCH(B37,$A$14:$A$16,0)))/1000000,"")) | G37: =IF(F37="","",F37/$B$5) | H37: =IF(G37="","",SUM($G$34:G37))
F38: =IF(OR(D38="",E38=""),"",IFERROR((D38*INDEX($C$14:$C$16,MATCH(B38,$A$14:$A$16,0))+E38*INDEX($D$14:$D$16,MATCH(B38,$A$14:$A$16,0)))/1000000,"")) | G38: =IF(F38="","",F38/$B$5) | H38: =IF(G38="","",SUM($G$34:G38))
F39: =IF(OR(D39="",E39=""),"",IFERROR((D39*INDEX($C$14:$C$16,MATCH(B39,$A$14:$A$16,0))+E39*INDEX($D$14:$D$16,MATCH(B39,$A$14:$A$16,0)))/1000000,"")) | G39: =IF(F39="","",F39/$B$5) | H39: =IF(G39="","",SUM($G$34:G39))
F40: =IF(OR(D40="",E40=""),"",IFERROR((D40*INDEX($C$14:$C$16,MATCH(B40,$A$14:$A$16,0))+E40*INDEX($D$14:$D$16,MATCH(B40,$A$14:$A$16,0)))/1000000,"")) | G40: =IF(F40="","",F40/$B$5) | H40: =IF(G40="","",SUM($G$34:G40))
F41: =IF(OR(D41="",E41=""),"",IFERROR((D41*INDEX($C$14:$C$16,MATCH(B41,$A$14:$A$16,0))+E41*INDEX($D$14:$D$16,MATCH(B41,$A$14:$A$16,0)))/1000000,"")) | G41: =IF(F41="","",F41/$B$5) | H41: =IF(G41="","",SUM($G$34:G41))
F42: =IF(OR(D42="",E42=""),"",IFERROR((D42*INDEX($C$14:$C$16,MATCH(B42,$A$14:$A$16,0))+E42*INDEX($D$14:$D$16,MATCH(B42,$A$14:$A$16,0)))/1000000,"")) | G42: =IF(F42="","",F42/$B$5) | H42: =IF(G42="","",SUM($G$34:G42))
F43: =IF(OR(D43="",E43=""),"",IFERROR((D43*INDEX($C$14:$C$16,MATCH(B43,$A$14:$A$16,0))+E43*INDEX($D$14:$D$16,MATCH(B43,$A$14:$A$16,0)))/1000000,"")) | G43: =IF(F43="","",F43/$B$5) | H43: =IF(G43="","",SUM($G$34:G43))
F44: =IF(OR(D44="",E44=""),"",IFERROR((D44*INDEX($C$14:$C$16,MATCH(B44,$A$14:$A$16,0))+E44*INDEX($D$14:$D$16,MATCH(B44,$A$14:$A$16,0)))/1000000,"")) | G44: =IF(F44="","",F44/$B$5) | H44: =IF(G44="","",SUM($G$34:G44))
...

Sheet Paramètres
A1: PARAMÈTRES DU PILOTAGE
A3: Statut | B3: Poids d’avancement | C3: Signification
A4: À faire | B4: 0 | C4: Pas commencé
A5: En cours | B5: 0.4 | C5: Production en cours
A6: À valider | B6: 0.75 | C6: Produit, en attente de relecture / validation
A7: Validé | B7: 1 | C7: Relu et validé (maths, pédagogie, qualité)
A9: Hypothèse : les poids (0 %, 40 %, 75 %, 100 %) sont une proposition de départ. Modifiez les cellules jaunes pour changer le calcul d’avancement partout.
A11: Vague | B11: Contenu | C11: Justification
A12: V0 – Pilote | B12: N22 (tranche verticale complète) | C12: Valider la méthode et le niveau de qualité avant la production en série.
A13: MVP | B13: N10, N11, N17–N21, N23, N62–N64 (avec N22 pilote) | C13: Première version testable pour le CM2 : prérequis de calcul, chapitre Fractions complet, résolution de problèmes.
A14: V1 | B14: N01–N16 : numération, décimaux, calcul (hors notions MVP) | C14: Prérequis des autres notions.
A15: V2 | B15: N17–N30 : fractions, proportionnalité | C15: Cœur du CEP ; s’appuie sur la division et les décimaux.
A16: V3 | B16: N31–N54 : mesures, géométrie plane, périmètres et aires | C16: Notions procédurales et visuelles.
A17: V4 | B17: N55–N68 : espace, échelles, résolution de problèmes | C17: Notions de synthèse qui mobilisent les précédentes.
A18: Hypothèse : découpage en vagues proposé par l’assistant (ordre des prérequis). Le document maître prévoit une production « en vagues » sans fixer leur contenu.

Sheet Revue documentaire
A1: REVUE DOCUMENTAIRE – RECHERCHES UTILES AU PARCOURS ET AU STYLE PÉDAGOGIQUE
A2: Méthode : les sources ci-dessous ont été retrouvées par recherche web (septembre 2026). Sauf mention contraire, l’assistant a lu des résumés, des pages de synthèse ou des extraits, pas les articles complets : statut « Résumé lu ». Les chiffres sont ceux rapportés par ces sources. Les études ne concernent pas toutes des élèves de primaire ni le Bénin : voir la colonne « Limites ».
A4: N° | B4: Thème | C4: Source | D4: Type d’étude et contexte | E4: Résultat principal (rapporté) | F4: Ce que cela implique pour Mathéo | G4: Limites / fiabilité | H4: Preuve | I4: Statut | J4: Lien | K4: Ajouté le
A5: 1 | B5: IA tutrice | C5: Bastani, Bastani, Sungu et al. (2025), PNAS ; version 2024 sur SSRN | D5: Essai contrôlé, environ 1 000 lycéens, cours de maths. Deux tuteurs GPT-4 : version standard et version avec garde-fous. | E5: La version standard améliore les résultats à l’entraînement (+48 %) mais les élèves réussissent 17 % moins bien à l’examen sans IA. Le tuteur avec garde-fous (+127 % à l’entraînement) supprime ce préjudice, sans bénéfice net mesuré à l’examen. | F5: Mathéo n’est jamais une IA qui donne la réponse. Indices progressifs, effort de l’enfant d’abord, évaluation « Boss » sans aide de l’IA. | G5: Lycéens (pas primaire), un seul pays, GPT-4. Le sens général est très cité. | H5: Élevée | I5: Résumé lu | J5: https://scale.stanford.edu/publications/generative-ai-can-harm-learning | K5: 2026-09-30
A6: 2 | B6: IA tutrice | C6: De Simone, Tiberti, Barron Rodriguez et al. (2025), Banque mondiale, « From Chalkboards to Chatbots » | D6: Essai contrôlé, 9 écoles publiques (Edo, Nigeria), 6 semaines après l’école, élèves en binômes avec GPT-4 sous supervision d’un enseignant, consignes favorisant le raisonnement. | E6: +0,31 écart-type (anglais : +0,23), soit environ 1,5 à 2 ans de scolarité ordinaire selon les auteurs. Plus de séances suivies, plus de gains. | F6: L’IA fonctionne dans un cadre structuré, avec un adulte qui anime. Prévoir un mode classe supervisé avant tout usage libre à la maison. | G6: Secondaire, anglais (pas maths), programme encadré. Effets à transposer avec prudence au primaire. | H6: Élevée | I6: Résumé lu | J6: https://documents.worldbank.org/en/publication/documents-reports/documentdetail/099548105192529324 | K6: 2026-09-30
A7: 3 | B7: IA tutrice | C7: UNESCO (2023), Guide pour l’IA générative en éducation ; couverture AFP | D7: Orientations pour les États. Seule la couverture de presse a été lue. | E7: Met en garde contre l’effet sur le bien-être émotionnel et la manipulation des enfants. Mentionne le seuil de 13 ans utilisé par ChatGPT, que beaucoup jugent trop bas (16 ans proposé). Les comptes rendus divergent sur la formulation exacte. | F7: Chat libre réservé aux contextes supervisés ; pas d’attachement artificiel ; avis juridique local avant ouverture aux 8-11 ans. | G7: Source secondaire (presse). Lire le guide original. | H7: Moyenne | I7: Résumé lu | J7: https://techxplore.com/news/2023-09-age-limits-ai-tools-schools.amp | K7: 2026-09-30
A8: 4 | B8: Fractions | C8: Fuchs, Malone, Schumacher, Namkung, Wang (2017), Journal of Learning Disabilities : 5 essais contrôlés | D8: Programme « Fraction Face-Off! », élèves de 4e année à risque, petits groupes, 12 semaines. Approche centrée sur la grandeur des fractions et la droite numérique. | E8: Effet moyen rapporté : 0,64 (N = 212). Comprendre qu’une fraction est un nombre placé sur une droite graduée améliore la compréhension et le calcul. | F8: Dans N17 à N23, ajouter la droite graduée et la comparaison de grandeurs, en plus des parts de gâteau. À intégrer dans les leçons N19, N20, N21. | G8: Élèves américains à risque, animés par des adultes. Effet à confirmer en autonomie sur écran. | H8: Élevée | I8: Résumé lu | J8: https://edknowledge.stanford.edu/node/274 | K8: 2026-09-30
A9: 5 | B9: Fractions | C9: Malone, Fuchs, Sterba, Fuchs, Foreman-Murray (2019), Contemporary Educational Psychology | D9: Essai contrôlé, N = 225 élèves de 4e année, comparaison fractions seules, fractions + décimaux intégrés, fractions + applications. | E9: Le programme sur la grandeur des fractions améliore la compréhension (effet 0,29) et se transfère aux décimaux sur droite numérique. Intégrer les décimaux au programme des fractions n’ajoute pas de bénéfice supplémentaire. | F9: Ne pas fusionner fractions et décimaux dans les mêmes leçons ; un lien explicite suffit dans la progression. | G9: Même limites que la ligne précédente. | H9: Élevée | I9: Résumé lu | J9: https://edknowledge.stanford.edu/node/273 | K9: 2026-09-30
A10: 6 | B10: Parcours et niveau | C10: J-PAL (synthèse) : Teaching at the Right Level (Pratham) et logiciels adaptatifs (Mindspark, programme de remédiation en jeu) | D10: Six évaluations aléatoires dans sept États indiens pour TaRL ; deux programmes numériques adaptatifs. | E10: TaRL : +0,07 à +0,70 écart-type ; les élèves les plus faibles progressent le plus. Mindspark : +0,37 en maths après 4,5 mois. Programme de remédiation en jeu : +0,47 la 2e année. | F10: Test de positionnement à l’entrée, parcours adapté au niveau réel (pas seulement à la classe déclarée), retour aux prérequis, remédiation ciblée. | G10: Inde, dispositifs avec encadrement. Bonne pertinence pour un contexte de faible niveau initial. | H10: Élevée | I10: Résumé lu | J10: https://www.povertyactionlab.org/ar/print/pdf/node/4537?lang=en | K10: 2026-09-30
A11: 7 | B11: Application de maths en Afrique | C11: Pitchford (2015), Frontiers in Psychology ; Hubber et al. (2016) ; couverture Univ. de Nottingham et presse | D11: Essai contrôlé de 8 semaines, 283 élèves des classes 1 à 3 à Lilongwe (Malawi). Applications onebillion, environ 30 minutes par jour, audio en chichewa, progression conditionnée à un score de 10/10, petits groupes. | E11: Connaissances du programme : d = 0,75 ; connaissances conceptuelles : d = 0,23. Le Malawi a ensuite étendu le programme à plusieurs centaines d’écoles. | F11: Séances d’environ 30 minutes, maîtrise avant de passer à la suite, audio dans la langue de l’enfant, usage en petits groupes possible. Seuil de maîtrise à calibrer (10/10 ou moins). | G11: Élèves des classes 1 à 3 avec un contenu conçu pour de jeunes enfants, un seul essai initial, une école urbaine. Les formules de presse (« 18 mois en 6 semaines ») sont à manier avec prudence. | H11: Moyenne à élevée | I11: Résumé lu | J11: https://pmc.ncbi.nlm.nih.gov/articles/PMC4893577 | K11: 2026-09-30
A12: 8 | B12: Style visuel et narratif | C12: Sundararajan et Adesope (2020), Educational Psychology Review ; Rey (2012) ; méta-analyse AERA 2026 | D12: Méta-analyse de 58 études (plus de 7 500 élèves) sur les « détails séduisants » : éléments attrayants mais sans lien avec la notion. | E12: Effet négatif sur l’apprentissage (g = −0,33 dans une synthèse ; −0,16 dans une méta-analyse plus récente). Plus marqué quand l’élément est fixe et constant, et via la surcharge cognitive. Une étude de 2025 montre que des images liées au concept peuvent aider. | F12: L’histoire doit être intégrée au calcul : les objets de l’histoire sont les objets des maths (mangues, pièces du vaisseau). Pas de décor animé ni d’effets à côté des calculs. Intrigue avant et après la notion, pas pendant. | G12: Les effets varient selon le contexte et l’âge ; les enfants ont une mémoire de travail plus limitée. À vérifier sur des enfants béninois. | H12: Élevée | I12: Résumé lu | J12: https://news.wsu.edu/2020/03/19/seductive-details-inhibit-learning/ | K12: 2026-09-30
A13: 9 | B13: Révision et pratique | C13: Rohrer, Dedrick, Hartwig, Cheung (2020), Journal of Educational Psychology | D13: Essai contrôlé en grappes, 54 classes de 7e année, 4 mois. Exercices mélangés (deux problèmes consécutifs n’utilisent jamais la même stratégie) contre exercices groupés par type. | E13: Test surprise un mois plus tard : 61 % contre 38 % (d = 0,83). Les enseignants l’ont mis en œuvre sans formation. | F13: La rubrique Révision propose des séries mélangées et espacées (rappel à quelques jours). Pour un premier apprentissage d’une notion, garder des séries groupées avant de mélanger (hypothèse de l’assistant à tester). | G13: Collège (pas primaire). Le temps de pratique est plus long. | H13: Élevée | I13: Résumé lu | J13: https://ies.ed.gov/use-work/awards/efficacy-study-interleaved-mathematics-practice | K13: 2026-09-30
A14: 10 | B14: Ordre de la leçon | C14: Sinha et Kapur (2021), Review of Educational Research | D14: Méta-analyse de 53 études (166 comparaisons) : résoudre un problème avant l’explication (« échec productif ») contre explication d’abord. | E14: Meilleure compréhension conceptuelle et meilleur transfert avec le problème d’abord. Les auteurs précisent que cela demande des connaissances préalables ; l’approche a moins bien fonctionné chez les plus jeunes ; la plupart des élèves avaient 12 à 18 ans ; le travail en petits groupes aide. | F14: Correction de mon conseil précédent : le défi avant l’explication doit être guidé et n’est utile que si les prérequis sont maîtrisés. Sinon, commencer par un exemple résolu. À tester sur des élèves de CM2. | G14: 15 % seulement des élèves étaient au primaire. Résultats à confirmer à cet âge. | H14: Élevée (mais transfert incertain) | I14: Résumé lu | J14: https://evidencebasedliving.human.cornell.edu/blog/to-better-learn-students-must-first-fail | K14: 2026-09-30
A15: 11 | B15: Jeu et motivation | C15: Sailer et Homner (2019), Educational Psychology Review | D15: Méta-analyse sur la ludification de l’apprentissage. | E15: Petits effets positifs : cognitif g = 0,49, motivationnel g = 0,36, comportemental g = 0,25. Les effets sur la motivation et le comportement sont moins stables dans les études les plus rigoureuses. | F15: Le jeu aide, sans être magique. Récompenses liées à la progression personnelle et à la coopération, pas de classement compétitif. Le résultat du jeu doit dépendre de la maîtrise réelle. | G15: Peu de résultats spécifiques au primaire et au Bénin. Une étude de synthèse (Algarve) recommande d’équilibrer compétition, maîtrise et coopération : à relire. | H15: Moyenne à élevée | I15: Résumé lu | J15: https://opus.bibliothek.uni-augsburg.de/opus4/files/109056/109056.pdf | K15: 2026-09-30
A16: 12 | B16: Vidéo | C16: Guo, Kim, Rubin (2014), Learning at Scale (edX) | D16: Analyse de 6,9 millions de sessions de visionnage sur des cours en ligne. | E16: L’engagement chute nettement après environ 6 minutes. Les vidéos plus personnelles et les tracés à la main de type tableau sont plus engageants. | F16: Vidéos « pour les nuls » de 2 à 4 minutes, une seule idée, ton informel, tracé à la main et voix. Découper les notions complexes en capsules. | G16: Adultes (cours en ligne), engagement mesuré, pas apprentissage. À vérifier avec des enfants. | H16: Moyenne | I16: Résumé lu | J16: https://www.cs.rochester.edu/hci/pubs/pdfs/edX-MOOC-video-production-and-engagement_LAS-2014.pdf | K16: 2026-09-30
... A19: 15 | B19: Technique : coûts API | C19: Tarifs publics de DeepSeek V4 Flash (plusieurs comparateurs, août-septembre 2026) | D19: Pages de tarifs et calculateurs. | E19: Environ 0,14 $ par million de tokens en entrée et 0,28 $ en sortie ; certains comparateurs affichent des prix plus bas. Pas d’offre gratuite permanente sur l’API officielle. | F19: Une question d’élève coûte de l’ordre de quelques centièmes de centime de dollar : prévoir un budget d’IA en production, avec plafonds par enfant. | G19: Tarifs susceptibles de changer sans préavis. Vérifier à la source avant décision. | H19: Moyenne | I19: Résumé lu | J19: https://trevorfox.com/tools/calculators/llm-cost/deepseek/deepseek-v4-flash/ | K19: 2026-09-30
A20: 16 | B20: Langue d’enseignement | E20: Effet de la langue (français, langues locales) sur l’apprentissage des maths au primaire au Bénin ; audio en langue locale (piste ouverte par le cas du Malawi). | I20: À rechercher
A21: 17 | B21: Représentations | E21: Concret, imagé, abstrait (CRA) et estompage du concret pour les fractions et la proportionnalité. | I21: À rechercher
A22: 18 | B22: Exemples résolus | E22: Exemples résolus et retrait progressif de l’aide ; inversion de l’effet d’expertise. | I22: À rechercher
A23: 19 | B23: Retour d’information | E23: Type et moment de la correction (immédiate ou différée), retours centrés sur l’erreur en maths. | I23: À rechercher
A24: 20 | B24: Émotions | E24: Anxiété mathématique, état d’esprit de croissance, effet des récompenses sur la motivation intrinsèque chez les 8-11 ans. | I24: À rechercher
A25: 21 | B25: Séances | E25: Durée et fréquence optimales chez les 8 à 11 ans ; usage en classe ou à la maison ; place de l’adulte. | I25: À rechercher
A26: 22 | B26: Contexte béninois | E26: Résultats PASEC et difficultés courantes au CEP au Bénin ; équipement réel des familles et coût des données ; accès des filles. | I26: À rechercher
A27: 23 | B27: Programme officiel | E27: Programme officiel de mathématiques (CE2, CM1, CM2) et critères d’homologation des ressources numériques. | I27: À rechercher
A28: 24 | B28: Mémorisation | E28: Pratique de rappel et espacement en primaire (au-delà de l’essai en 7e année). | I28: À rechercher
A29: 25 | B29: Narration | E29: Personnalisation et contextualisation des problèmes de maths (histoires) : effets sur la compréhension et limites. | I29: À rechercher

Sheet Principes de conception
A1: PRINCIPES DE CONCEPTION DÉRIVÉS DE LA REVUE DOCUMENTAIRE
A2: Propositions de l’assistant, à valider par le porteur du projet, des enseignants béninois et des tests avec des enfants. Les numéros renvoient à la colonne N° de la feuille « Revue documentaire ».
A4: N° | B4: Principe | C4: Fondé sur (revue n°) | D4: Où il s’applique | E4: Force de la preuve | F4: Statut
A5: 1 | B5: Chaque enfant commence par un test de positionnement court ; le parcours suit son niveau réel, avec retour aux prérequis, pas seulement sa classe déclarée. | C5: 6 | D5: Parcours, moteur de diagnostic | E5: Élevée | F5: À valider
A6: 2 | B6: La leçon repose sur la maîtrise : on passe à la suite quand la notion est acquise (seuil à calibrer), avec remédiation ciblée avant. | C6: 6, 7 | D6: Parcours, quiz | E6: Moyenne à élevée | F6: À valider
A7: 3 | B7: Fractions : la droite graduée et la comparaison de grandeurs sont centrales dès N17, en plus des parts de gâteau. Fractions et décimaux restent des blocs distincts, reliés explicitement. | C7: 4, 5 | D7: Leçons N17 à N23, vidéos, BD | E7: Élevée | F7: À valider
A8: 4 | B8: Défi avant explication seulement s’il est guidé et si les prérequis sont maîtrisés ; sinon exemple résolu d’abord. | C8: 10 | D8: Ordre des étapes de la leçon | E8: Élevée (transfert incertain) | F8: À tester
A9: 5 | B9: L’histoire est intégrée au calcul : les objets de l’histoire sont les objets des maths ; pas d’animation décorative pendant la résolution. | C9: 8 | D9: BD, écrans de jeu, illustrations | E9: Élevée | F9: À valider
A10: 6 | B10: Vidéos de 2 à 4 minutes, une idée par vidéo, ton informel, tracé à la main avec voix ; capsules séparées pour les notions complexes. | C10: 12 | D10: Vidéos | E10: Moyenne | F10: À valider
A11: 7 | B11: Séance type d’environ 15 à 30 minutes, avec une fin claire et un suspense narratif. | C11: 7 | D11: Conception des séances | E11: Moyenne | F11: À tester
A12: 8 | B12: La rubrique Révision mélange et espace les exercices ; les séries groupées servent au premier apprentissage. | C12: 9 | D12: Révision, quiz | E12: Élevée (collège) | F12: À tester
A13: 9 | B13: Révision libre pour les notions déjà travaillées ; parcours guidé et recommandations pour les nouvelles. | C13: 13 | D13: Interface, rubrique Révision | E13: Moyenne | F13: À valider
A14: 10 | B14: Mathéo donne des indices avant la solution, exige un essai de l’enfant, montre un exemple similaire, propose « Vérifie ma réponse ». | C14: 1, 2 | D14: IA tutrice | E14: Élevée | F14: À valider
A15: 11 | B15: L’IA conversationnelle est réservée à des contextes supervisés (classe ou compte parent) au départ ; avis juridique avant ouverture. | C15: 2, 3 | D15: IA tutrice, gouvernance | E15: Moyenne | F15: À valider
A16: 12 | B16: L’évaluation finale (Boss, CEP blanc) se fait sans IA pour mesurer l’apprentissage réel. | C16: 1 | D16: Boss, CEP | E16: Élevée | F16: À valider
... A20: 16 | B20: Contrainte matérielle : tablette de référence à 3 Go de RAM et 32 Go de stockage. Application légère, contenus téléchargés par niveau, pas d’IA embarquée, voix et animations pré-générées, saisie à l’écran plutôt que photo si la caméra est faible. | C20: Contrainte du projet (porteur) | D20: Architecture, production des médias, IA | E20: Contrainte technique | F20: À valider

Sheet Budget exploitation
A1: BUDGET D’EXPLOITATION – IA SANS LIMITE DE QUESTIONS NI DE PHOTOS
A2: Estimation de l’assistant. Cellules jaunes à fond bleu : hypothèses à modifier. Tarifs de l’API de DeepSeek V4 Flash (texte) et de sa version Vision expérimentale (photos), sept. 2026, à revérifier. Hors développement, contenus, personnel, assistance.
A3: Paramètre commun | B3: Valeur | C3: Note
A4: Élèves année 1 | B4: 3000 | C4: Décision du porteur du projet.
A5: Élèves année 2 | B5: 6000 | C5: Décision du porteur du projet.
A6: Jours d’usage par mois | B6: 30 | C6: Prudent : inclut les week-ends.
A7: Mois d’usage par an | B7: 10 | C7: Hypothèse : année scolaire.
A8: Prix texte en entrée ($/M tokens) | B8: 0.14 | C8: DeepSeek V4 Flash ; les sources varient.
A9: Prix texte en sortie ($/M tokens) | B9: 0.28 | C9: Idem.
A10: Prix vision en entrée ($/M tokens) | B10: 0.22 | C10: Version Vision expérimentale (août 2026).
A11: Prix vision en sortie ($/M tokens) | B11: 0.66 | C11: Idem.
A12: Tokens d’entrée par question texte | B12: 1500 | C12: Hypothèse (consigne + contexte + question).
A13: Tokens de sortie par réponse texte | B13: 500 | C13: Hypothèse. Réponses courtes = moins cher.
A14: Tokens d’entrée par question photo | B14: 3500 | C14: Hypothèse (image + consigne).
A15: Tokens de sortie par réponse photo | B15: 600 | C15: Hypothèse.
A16: Infrastructure ($/mois) | B16: 125 | C16: Serveurs, sauvegardes, domaine : estimation, à remplacer par des devis béninois.
A17: Coût d’une question texte ($) | B17: =(B12*B8+B13*B9)/1000000 -> 0.00035
A18: Coût d’une question photo ($) | B18: =(B14*B10+B15*B11)/1000000 -> 0.001166
A20: Scénario | B20: Moyen | C20: Intense | D20: Moyen optimisé | E20: Intense optimisé
A21: Part d’élèves actifs par jour | B21: 0.4 | C21: 0.7 | D21: 0.4 | E21: 0.7
A22: Interactions par élève actif et par jour | B22: 8 | C22: 15 | D22: 8 | E22: 15
A23: Part des interactions avec photo | B23: 0.25 | C23: 0.4 | D23: 0.25 | E23: 0.4
A24: Part des réponses réutilisées (exercices identiques déjà expliqués) | B24: 0 | C24: 0 | D24: 0.6 | E24: 0.5
A25: Économie sur le reste (cache de consigne, réponses courtes) | B25: 0 | C25: 0 | D25: 0.4 | E25: 0.4
A26: Coût moyen par interaction ($) | B26: =((1-B23)*$B$17+B23*$B$18)*(1-B24)*(1-B25) -> 0.000554 | C26: =((1-C23)*$B$17+C23*$B$18)*(1-C24)*(1-C25) -> 0.0006764 | D26: =((1-D23)*$B$17+D23*$B$18)*(1-D24)*(1-D25) -> 0.00013296 | E26: =((1-E23)*$B$17+E23*$B$18)*(1-E24)*(1-E25) -> 0.00020292
A27: Interactions par jour, année 1 | B27: =$B$4*B21*B22 -> 9600 | C27: =$B$4*C21*C22 -> 31500 | D27: =$B$4*D21*D22 -> 9600 | E27: =$B$4*E21*E22 -> 31500
A28: Interactions par jour, année 2 | B28: =$B$5*B21*B22 -> 19200 | C28: =$B$5*C21*C22 -> 63000 | D28: =$B$5*D21*D22 -> 19200 | E28: =$B$5*E21*E22 -> 63000
A29: Coût IA par mois, année 1 ($) | B29: =B27*B26*$B$6 -> 159.552 | C29: =C27*C26*$B$6 -> 639.198 | D29: =D27*D26*$B$6 -> 38.29248 | E29: =E27*E26*$B$6 -> 191.7594
A30: Coût IA par mois, année 2 ($) | B30: =B28*B26*$B$6 -> 319.104 | C30: =C28*C26*$B$6 -> 1278.396 | D30: =D28*D26*$B$6 -> 76.58496 | E30: =E28*E26*$B$6 -> 383.5188
A31: Total par mois, année 1 ($) avec infrastructure | B31: =B29+$B$16 -> 284.552 | C31: =C29+$B$16 -> 764.198 | D31: =D29+$B$16 -> 163.29248 | E31: =E29+$B$16 -> 316.7594
A32: Total par mois, année 2 ($) avec infrastructure | B32: =B30+$B$16 -> 444.104 | C32: =C30+$B$16 -> 1403.396 | D32: =D30+$B$16 -> 201.58496 | E32: =E30+$B$16 -> 508.5188
A33: Coût annuel, année 1 ($) | B33: =B29*$B$7+$B$16*12 -> 3095.52 | C33: =C29*$B$7+$B$16*12 -> 7891.98 | D33: =D29*$B$7+$B$16*12 -> 1882.9248 | E33: =E29*$B$7+$B$16*12 -> 3417.594
A34: Coût annuel, année 2 ($) | B34: =B30*$B$7+$B$16*12 -> 4691.04 | C34: =C30*$B$7+$B$16*12 -> 14283.96 | D34: =D30*$B$7+$B$16*12 -> 2265.8496 | E34: =E30*$B$7+$B$16*12 -> 5335.188
A35: Coût par élève et par an, année 1 ($) | B35: =B33/$B$4 -> 1.03184 | C35: =C33/$B$4 -> 2.63066 | D35: =D33/$B$4 -> 0.6276416 | E35: =E33/$B$4 -> 1.139198
A36: Coût par élève et par an, année 2 ($) | B36: =B34/$B$5 -> 0.78184 | C36: =C34/$B$5 -> 2.38066 | D36: =D34/$B$5 -> 0.3776416 | E36: =E34/$B$5 -> 0.889198
A38: Lecture : les colonnes « optimisé » supposent que la réutilisation des réponses et le cache réduisent la facture. Ce sont des hypothèses à mesurer pendant le pilote, pas des résultats.
A39: Aucune limite d’usage n’est visible pour l’élève. Les garde-fous sont techniques : limite par minute, taille maximale des photos, détection de robots, plafond de sécurité très élevé qui bascule vers les réponses en cache plutôt que de bloquer.
